<?xml version="1.0" encoding="utf-8"?>
<!-- =================================================================================== -->
<!-- |    This document was autogenerated by xacro from base_scene.urdf.xacro          | -->
<!-- |    EDITING THIS FILE BY HAND IS NOT RECOMMENDED                                 | -->
<!-- =================================================================================== -->
<robot name="buggy_scene">
  <!-- This creates a box with the origin in the bottom corner, fixed to the world link. -->
  <link name="vertical_column_right">
    <!-- w is in x, l is in y, h is in z -->
    <visual>
      <origin rpy="0 0 0" xyz="0.02 0.02 1.0"/>
      <geometry>
        <box size="0.04 0.04 2.0"/>
      </geometry>
      <material name="Grey">
        <color rgba="0.7 0.7 0.7 1.0"/>
      </material>
    </visual>
    <collision>
      <origin rpy="0 0 0" xyz="0.02 0.02 1.0"/>
      <geometry>
        <box size="0.04 0.04 2.0"/>
      </geometry>
    </collision>
    <inertial>
      <mass value="1.0"/>
      <inertia ixx="0.0" ixy="0.0" ixz="0.0" iyy="0.0" iyz="0.0" izz="0.0"/>
    </inertial>
  </link>
  <gazebo reference="vertical_column_right">
    <material>Gazebo/Grey</material>
  </gazebo>
  <joint name="vertical_column_right" type="fixed">
    <parent link="my_ground"/>
    <child link="vertical_column_right"/>
    <origin rpy="0 0 0" xyz="-0.515 .2 0"/>
  </joint>
  <!-- This creates a box with the origin in the bottom corner, fixed to the world link. -->
  <link name="vertical_column_left">
    <!-- w is in x, l is in y, h is in z -->
    <visual>
      <origin rpy="0 0 0" xyz="0.02 0.02 1.0"/>
      <geometry>
        <box size="0.04 0.04 2.0"/>
      </geometry>
      <material name="Grey">
        <color rgba="0.7 0.7 0.7 1.0"/>
      </material>
    </visual>
    <collision>
      <origin rpy="0 0 0" xyz="0.02 0.02 1.0"/>
      <geometry>
        <box size="0.04 0.04 2.0"/>
      </geometry>
    </collision>
    <inertial>
      <mass value="1.0"/>
      <inertia ixx="0.0" ixy="0.0" ixz="0.0" iyy="0.0" iyz="0.0" izz="0.0"/>
    </inertial>
  </link>
  <gazebo reference="vertical_column_left">
    <material>Gazebo/Grey</material>
  </gazebo>
  <joint name="vertical_column_left" type="fixed">
    <parent link="my_ground"/>
    <child link="vertical_column_left"/>
    <origin rpy="0 0 0" xyz="-0.515 -.24 0"/>
  </joint>
  <!-- This creates a box with the origin in the bottom corner, fixed to the world link. -->
  <link name="horizontal_column_top">
    <!-- w is in x, l is in y, h is in z -->
    <visual>
      <origin rpy="0 0 0" xyz="0.02 0.2 0.02"/>
      <geometry>
        <box size="0.04 0.4 0.04"/>
      </geometry>
      <material name="Grey">
        <color rgba="0.7 0.7 0.7 1.0"/>
      </material>
    </visual>
    <collision>
      <origin rpy="0 0 0" xyz="0.02 0.2 0.02"/>
      <geometry>
        <box size="0.04 0.4 0.04"/>
      </geometry>
    </collision>
    <inertial>
      <mass value="1.0"/>
      <!-- <origin xyz="${box_w/2} ${box_l} ${box_h/2}" rpy="0 0 0"/> -->
      <inertia ixx="0.0" ixy="0.0" ixz="0.0" iyy="0.0" iyz="0.0" izz="0.0"/>
    </inertial>
  </link>
  <gazebo reference="horizontal_column_top">
    <material>Gazebo/Grey</material>
  </gazebo>
  <joint name="horizontal_column_top" type="fixed">
    <parent link="my_ground"/>
    <child link="horizontal_column_top"/>
    <origin rpy="0 0 0" xyz="-0.515 -.2 1.96"/>
  </joint>
  <!-- This creates a box with the origin in the bottom corner, fixed to the world link. -->
  <link name="horizontal_column_for_tools">
    <!-- w is in x, l is in y, h is in z -->
    <visual>
      <origin rpy="0 0 0" xyz="0.02 0.2 0.02"/>
      <geometry>
        <box size="0.04 0.4 0.04"/>
      </geometry>
      <material name="Grey">
        <color rgba="0.7 0.7 0.7 1.0"/>
      </material>
    </visual>
    <collision>
      <origin rpy="0 0 0" xyz="0.02 0.2 0.02"/>
      <geometry>
        <box size="0.04 0.4 0.04"/>
      </geometry>
    </collision>
    <inertial>
      <mass value="1.0"/>
      <!-- <origin xyz="${box_w/2} ${box_l} ${box_h/2}" rpy="0 0 0"/> -->
      <inertia ixx="0.0" ixy="0.0" ixz="0.0" iyy="0.0" iyz="0.0" izz="0.0"/>
    </inertial>
  </link>
  <gazebo reference="horizontal_column_for_tools">
    <material>Gazebo/Grey</material>
  </gazebo>
  <joint name="horizontal_column_for_tools" type="fixed">
    <parent link="my_ground"/>
    <child link="horizontal_column_for_tools"/>
    <origin rpy="0 0 0" xyz="-0.515 -.2 1.058"/>
  </joint>
  <!-- TV -->
  <link name="tv">
    <visual>
      <origin rpy="0 0 0" xyz="-0.03 0.0 0.28"/>
      <geometry>
        <box size="0.06 0.96 0.56"/>
      </geometry>
      <material name="Black">
        <color rgba="0.1 0.1 0.1 1.0"/>
      </material>
    </visual>
    <collision>
      <origin rpy="0 0 0" xyz="-0.03 0.0 0.28"/>
      <geometry>
        <!-- 7.5 cm on each side -->
        <box size="0.21 1.11 0.66"/>
      </geometry>
    </collision>
    <inertial>
      <mass value="1.0"/>
      <inertia ixx="0.0" ixy="0.0" ixz="0.0" iyy="0.0" iyz="0.0" izz="0.0"/>
    </inertial>
  </link>
  <gazebo reference="tv">
    <material>Gazebo/Black</material>
  </gazebo>
  <joint name="tv_joint" type="fixed">
    <parent link="my_ground"/>
    <child link="tv"/>
    <origin rpy="0 0 0" xyz="-0.4 0.0 1.58"/>
  </joint>
  <!-- This creates a box with the origin in the bottom corner, fixed to the world link. -->
  <link name="a_bot_base_smfl">
    <!-- w is in x, l is in y, h is in z -->
    <visual>
      <origin rpy="0 0 0" xyz="0.325 0.325 0.025"/>
      <geometry>
        <box size="0.65 0.65 0.05"/>
      </geometry>
      <material name="DarkGrey">
        <color rgba="0.2 0.2 0.2 1.0"/>
      </material>
    </visual>
    <collision>
      <origin rpy="0 0 0" xyz="0.325 0.325 0.025"/>
      <geometry>
        <box size="0.65 0.65 0.05"/>
      </geometry>
    </collision>
    <inertial>
      <mass value="1.0"/>
      <!-- <origin xyz="${box_w/2} ${box_l} ${box_h/2}" rpy="0 0 0"/> -->
      <inertia ixx="0.0" ixy="0.0" ixz="0.0" iyy="0.0" iyz="0.0" izz="0.0"/>
    </inertial>
  </link>
  <gazebo reference="a_bot_base_smfl">
    <material>Gazebo/FlatBlack</material>
  </gazebo>
  <joint name="a_bot_base_smfl" type="fixed">
    <parent link="my_ground"/>
    <child link="a_bot_base_smfl"/>
    <origin rpy="0 0 0" xyz="-0.329 -0.85 0.7"/>
  </joint>
  <!-- This creates a box with the origin in the bottom corner, fixed to the world link. -->
  <link name="b_bot_base_smfl">
    <!-- w is in x, l is in y, h is in z -->
    <visual>
      <origin rpy="0 0 0" xyz="0.325 0.325 0.025"/>
      <geometry>
        <box size="0.65 0.65 0.05"/>
      </geometry>
      <material name="DarkGrey">
        <color rgba="0.2 0.2 0.2 1.0"/>
      </material>
    </visual>
    <collision>
      <origin rpy="0 0 0" xyz="0.325 0.325 0.025"/>
      <geometry>
        <box size="0.65 0.65 0.05"/>
      </geometry>
    </collision>
    <inertial>
      <mass value="1.0"/>
      <!-- <origin xyz="${box_w/2} ${box_l} ${box_h/2}" rpy="0 0 0"/> -->
      <inertia ixx="0.0" ixy="0.0" ixz="0.0" iyy="0.0" iyz="0.0" izz="0.0"/>
    </inertial>
  </link>
  <gazebo reference="b_bot_base_smfl">
    <material>Gazebo/FlatBlack</material>
  </gazebo>
  <joint name="b_bot_base_smfl" type="fixed">
    <parent link="my_ground"/>
    <child link="b_bot_base_smfl"/>
    <origin rpy="0 0 0" xyz="-0.325 0.2 0.7"/>
  </joint>
  <!-- This creates a box with the origin in the bottom corner, fixed to the world link. -->
  <link name="workplate">
    <!-- w is in x, l is in y, h is in z -->
    <visual>
      <origin rpy="0 0 0" xyz="0.325 0.2 0.01"/>
      <geometry>
        <box size="0.65 0.4 0.02"/>
      </geometry>
      <material name="Grey">
        <color rgba="0.7 0.7 0.7 1.0"/>
      </material>
    </visual>
    <collision>
      <origin rpy="0 0 0" xyz="0.325 0.2 0.01"/>
      <geometry>
        <box size="0.65 0.4 0.02"/>
      </geometry>
    </collision>
    <inertial>
      <mass value="1.0"/>
      <!-- <origin xyz="${box_w/2} ${box_l} ${box_h/2}" rpy="0 0 0"/> -->
      <inertia ixx="0.0" ixy="0.0" ixz="0.0" iyy="0.0" iyz="0.0" izz="0.0"/>
    </inertial>
  </link>
  <gazebo reference="workplate">
    <material>Gazebo/Grey</material>
  </gazebo>
  <joint name="workplate" type="fixed">
    <parent link="my_ground"/>
    <child link="workplate"/>
    <origin rpy="0 0 0" xyz="-0.325 -0.2 0.745"/>
  </joint>
  <link name="workspace_center"/>
  <joint name="world_to_workspace" type="fixed">
    <parent link="my_ground"/>
    <child link="workspace_center"/>
    <origin rpy="0.0 0.0 0.0" xyz="0.0 0.0 0.765"/>
  </joint>
  <!-- measured from model -->
  <!-- link lengths used in model -->
  <!-- manually measured -->
  <link name="a_bot_base_link">
    <visual>
      <origin rpy="0 0 3.14159265359" xyz="0 0 0"/>
      <geometry>
        <mesh filename="package://ur_e_description/meshes/ur5e/visual/base.dae"/>
      </geometry>
      <material name="LightGrey">
        <color rgba="0.7 0.7 0.7 1.0"/>
      </material>
    </visual>
    <collision>
      <origin rpy="0 0 3.14159265359" xyz="0 0 0"/>
      <geometry>
        <mesh filename="package://ur_e_description/meshes/ur5e/collision/base.stl"/>
      </geometry>
    </collision>
    <inertial>
      <mass value="4.0"/>
      <origin rpy="0 0 0" xyz="0.0 0.0 0.0"/>
      <inertia ixx="0.00443333156" ixy="0.0" ixz="0.0" iyy="0.00443333156" iyz="0.0" izz="0.0072"/>
    </inertial>
  </link>
  <joint name="a_bot_shoulder_pan_joint" type="revolute">
    <parent link="a_bot_base_link"/>
    <child link="a_bot_shoulder_link"/>
    <origin rpy="0 0 3.14159265094" xyz="0 0 0.162655931584"/>
    <axis xyz="0 0 1"/>
    <limit effort="150.0" lower="-3.14159265359" upper="3.14159265359" velocity="3.14"/>
    <dynamics damping="0.0" friction="0.0"/>
  </joint>
  <link name="a_bot_shoulder_link">
    <visual>
      <origin rpy="0 0 3.14159265359" xyz="0 0 0"/>
      <geometry>
        <mesh filename="package://ur_e_description/meshes/ur5e/visual/shoulder.dae"/>
      </geometry>
      <material name="LightGrey">
        <color rgba="0.7 0.7 0.7 1.0"/>
      </material>
    </visual>
    <collision>
      <origin rpy="0 0 3.14159265359" xyz="0 0 0"/>
      <geometry>
        <mesh filename="package://ur_e_description/meshes/ur5e/collision/shoulder.stl"/>
      </geometry>
    </collision>
    <inertial>
      <mass value="3.7"/>
      <origin rpy="0 0 0" xyz="0.0 0.0 0.0"/>
      <inertia ixx="0.010267495893" ixy="0.0" ixz="0.0" iyy="0.010267495893" iyz="0.0" izz="0.00666"/>
    </inertial>
  </link>
  <joint name="a_bot_shoulder_lift_joint" type="revolute">
    <parent link="a_bot_shoulder_link"/>
    <child link="a_bot_upper_arm_link"/>
    <origin rpy="1.56953512795 0 -2.84084164664e-07" xyz="0.000134779578882 0 0"/>
    <axis xyz="0 0 1"/>
    <limit effort="150.0" lower="-3.14159265359" upper="3.14159265359" velocity="3.14"/>
    <dynamics damping="0.0" friction="0.0"/>
  </joint>
  <link name="a_bot_upper_arm_link">
    <visual>
      <origin rpy="1.57079632679 0 -1.57079632679" xyz="0 0 0.138"/>
      <geometry>
        <mesh filename="package://ur_e_description/meshes/ur5e/visual/upperarm.dae"/>
      </geometry>
      <material name="LightGrey">
        <color rgba="0.7 0.7 0.7 1.0"/>
      </material>
    </visual>
    <collision>
      <origin rpy="1.57079632679 0 -1.57079632679" xyz="0 0 0.138"/>
      <geometry>
        <mesh filename="package://ur_e_description/meshes/ur5e/collision/upperarm.stl"/>
      </geometry>
    </collision>
    <inertial>
      <mass value="8.393"/>
      <origin rpy="0 1.57079632679 0" xyz="-0.212633383271 0.0 0.138"/>
      <inertia ixx="0.138293379943" ixy="0.0" ixz="0.0" iyy="0.138293379943" iyz="0.0" izz="0.0236053125"/>
    </inertial>
  </link>
  <joint name="a_bot_elbow_joint" type="revolute">
    <parent link="a_bot_upper_arm_link"/>
    <child link="a_bot_forearm_link"/>
    <origin rpy="0.000119395911412 0.00163456023303 5.12790813273e-07" xyz="-0.425266766542 0 0"/>
    <axis xyz="0 0 1"/>
    <limit effort="150.0" lower="0.0" upper="3.14159265359" velocity="3.14"/>
    <dynamics damping="0.0" friction="0.0"/>
  </joint>
  <link name="a_bot_forearm_link">
    <visual>
      <origin rpy="1.57079632679 0 -1.57079632679" xyz="0 0 0.007"/>
      <geometry>
        <mesh filename="package://ur_e_description/meshes/ur5e/visual/forearm.dae"/>
      </geometry>
      <material name="LightGrey">
        <color rgba="0.7 0.7 0.7 1.0"/>
      </material>
    </visual>
    <collision>
      <origin rpy="1.57079632679 0 -1.57079632679" xyz="0 0 0.007"/>
      <geometry>
        <mesh filename="package://ur_e_description/meshes/ur5e/collision/forearm.stl"/>
      </geometry>
    </collision>
    <inertial>
      <mass value="2.275"/>
      <origin rpy="0 1.57079632679 0" xyz="-0.212633383271 0.0 0.007"/>
      <inertia ixx="0.0324280715332" ixy="0.0" ixz="0.0" iyy="0.0324280715332" iyz="0.0" izz="0.0063984375"/>
    </inertial>
  </link>
  <joint name="a_bot_wrist_1_joint" type="revolute">
    <parent link="a_bot_forearm_link"/>
    <child link="a_bot_wrist_1_link"/>
    <origin rpy="0.00240514304011 -0.00147917631702 -3.8502770334e-07" xyz="-0.392650273076 -0.000321358811681 0.133612923084"/>
    <axis xyz="0 0 1"/>
    <limit effort="28.0" lower="-4.71238898038" upper="3.14159265359" velocity="6.28"/>
    <dynamics damping="0.0" friction="0.0"/>
  </joint>
  <link name="a_bot_wrist_1_link">
    <visual>
      <origin rpy="1.57079632679 0 0" xyz="0 0 -0.127"/>
      <geometry>
        <mesh filename="package://ur_e_description/meshes/ur5e/visual/wrist1.dae"/>
      </geometry>
      <material name="LightGrey">
        <color rgba="0.7 0.7 0.7 1.0"/>
      </material>
    </visual>
    <collision>
      <origin rpy="1.57079632679 0 0" xyz="0 0 -0.127"/>
      <geometry>
        <mesh filename="package://ur_e_description/meshes/ur5e/collision/wrist1.stl"/>
      </geometry>
    </collision>
    <inertial>
      <mass value="1.219"/>
      <origin rpy="0 0 0" xyz="0.0 0.0 0.0"/>
      <inertia ixx="0.00272444225937" ixy="0.0" ixz="0.0" iyy="0.00272444225937" iyz="0.0" izz="0.0034284375"/>
    </inertial>
  </link>
  <joint name="a_bot_wrist_2_joint" type="revolute">
    <parent link="a_bot_wrist_1_link"/>
    <child link="a_bot_wrist_2_link"/>
    <origin rpy="1.56963272494 0 9.63633041889e-08" xyz="8.31335451575e-05 -0.0997235522137 0.000116038562953"/>
    <axis xyz="0 0 1"/>
    <limit effort="28.0" lower="-4.71238898038" upper="4.71238898038" velocity="6.28"/>
    <dynamics damping="0.0" friction="0.0"/>
  </joint>
  <link name="a_bot_wrist_2_link">
    <visual>
      <origin rpy="0 0 0" xyz="0 0 -0.0997"/>
      <geometry>
        <mesh filename="package://ur_e_description/meshes/ur5e/visual/wrist2.dae"/>
      </geometry>
      <material name="LightGrey">
        <color rgba="0.7 0.7 0.7 1.0"/>
      </material>
    </visual>
    <collision>
      <origin rpy="0 0 0" xyz="0 0 -0.0997"/>
      <geometry>
        <mesh filename="package://ur_e_description/meshes/ur5e/collision/wrist2.stl"/>
      </geometry>
    </collision>
    <inertial>
      <mass value="1.219"/>
      <origin rpy="0 0 0" xyz="0.0 0.0 0.0"/>
      <inertia ixx="0.00272116872319" ixy="0.0" ixz="0.0" iyy="0.00272116872319" iyz="0.0" izz="0.0034284375"/>
    </inertial>
  </link>
  <joint name="a_bot_wrist_3_joint" type="revolute">
    <parent link="a_bot_wrist_2_link"/>
    <child link="a_bot_wrist_3_link"/>
    <origin rpy="1.57226982462 3.14159265359 3.14159261802" xyz="8.83928394576e-05 0.0995618487303 0.000146704273679"/>
    <axis xyz="0 0 1"/>
    <limit effort="28.0" lower="-6.28318530718" upper="6.28318530718" velocity="6.28"/>
    <dynamics damping="0.0" friction="0.0"/>
  </joint>
  <link name="a_bot_wrist_3_link">
    <visual>
      <origin rpy="1.57079632679 0 0" xyz="0 0 -0.0989"/>
      <geometry>
        <mesh filename="package://ur_e_description/meshes/ur5e/visual/wrist3.dae"/>
      </geometry>
      <material name="LightGrey">
        <color rgba="0.7 0.7 0.7 1.0"/>
      </material>
    </visual>
    <collision>
      <origin rpy="1.57079632679 0 0" xyz="0 0 -0.0989"/>
      <geometry>
        <mesh filename="package://ur_e_description/meshes/ur5e/collision/wrist3.stl"/>
      </geometry>
    </collision>
    <inertial>
      <mass value="0.1879"/>
      <origin rpy="0 0 0" xyz="0.0 0.0 -0.025"/>
      <inertia ixx="0.000134270154625" ixy="0.0" ixz="0.0" iyy="0.000134270154625" iyz="0.0" izz="0.00019024875"/>
    </inertial>
  </link>
  <joint name="a_bot_ee_fixed_joint" type="fixed">
    <parent link="a_bot_wrist_3_link"/>
    <child link="a_bot_ee_link"/>
    <origin rpy="0.0 -1.57079632679 1.57079632679" xyz="0.0 0.0 0.0"/>
  </joint>
  <link name="a_bot_ee_link">
    <collision>
      <geometry>
        <box size="0.01 0.01 0.01"/>
      </geometry>
      <origin rpy="0 0 0" xyz="-0.01 0 0"/>
    </collision>
  </link>
  <transmission name="a_bot_shoulder_pan_trans">
    <type>transmission_interface/SimpleTransmission</type>
    <joint name="a_bot_shoulder_pan_joint">
      <hardwareInterface>hardware_interface/PositionJointInterface</hardwareInterface>
    </joint>
    <actuator name="a_bot_shoulder_pan_motor">
      <mechanicalReduction>1</mechanicalReduction>
    </actuator>
  </transmission>
  <transmission name="a_bot_shoulder_lift_trans">
    <type>transmission_interface/SimpleTransmission</type>
    <joint name="a_bot_shoulder_lift_joint">
      <hardwareInterface>hardware_interface/PositionJointInterface</hardwareInterface>
    </joint>
    <actuator name="a_bot_shoulder_lift_motor">
      <mechanicalReduction>1</mechanicalReduction>
    </actuator>
  </transmission>
  <transmission name="a_bot_elbow_trans">
    <type>transmission_interface/SimpleTransmission</type>
    <joint name="a_bot_elbow_joint">
      <hardwareInterface>hardware_interface/PositionJointInterface</hardwareInterface>
    </joint>
    <actuator name="a_bot_elbow_motor">
      <mechanicalReduction>1</mechanicalReduction>
    </actuator>
  </transmission>
  <transmission name="a_bot_wrist_1_trans">
    <type>transmission_interface/SimpleTransmission</type>
    <joint name="a_bot_wrist_1_joint">
      <hardwareInterface>hardware_interface/PositionJointInterface</hardwareInterface>
    </joint>
    <actuator name="a_bot_wrist_1_motor">
      <mechanicalReduction>1</mechanicalReduction>
    </actuator>
  </transmission>
  <transmission name="a_bot_wrist_2_trans">
    <type>transmission_interface/SimpleTransmission</type>
    <joint name="a_bot_wrist_2_joint">
      <hardwareInterface>hardware_interface/PositionJointInterface</hardwareInterface>
    </joint>
    <actuator name="a_bot_wrist_2_motor">
      <mechanicalReduction>1</mechanicalReduction>
    </actuator>
  </transmission>
  <transmission name="a_bot_wrist_3_trans">
    <type>transmission_interface/SimpleTransmission</type>
    <joint name="a_bot_wrist_3_joint">
      <hardwareInterface>hardware_interface/PositionJointInterface</hardwareInterface>
    </joint>
    <actuator name="a_bot_wrist_3_motor">
      <mechanicalReduction>1</mechanicalReduction>
    </actuator>
  </transmission>
  <gazebo reference="a_bot_shoulder_link">
    <selfCollide>true</selfCollide>
  </gazebo>
  <gazebo reference="a_bot_upper_arm_link">
    <selfCollide>true</selfCollide>
  </gazebo>
  <gazebo reference="a_bot_forearm_link">
    <selfCollide>true</selfCollide>
  </gazebo>
  <gazebo reference="a_bot_wrist_1_link">
    <selfCollide>true</selfCollide>
  </gazebo>
  <gazebo reference="a_bot_wrist_3_link">
    <selfCollide>true</selfCollide>
  </gazebo>
  <gazebo reference="a_bot_wrist_2_link">
    <selfCollide>true</selfCollide>
  </gazebo>
  <gazebo reference="a_bot_ee_link">
    <selfCollide>true</selfCollide>
  </gazebo>
  <!-- ROS base_link to UR 'Base' Coordinates transform -->
  <link name="a_bot_base"/>
  <joint name="a_bot_base_link-base_fixed_joint" type="fixed">
    <!-- NOTE: this rotation is only needed as long as base_link itself is
                 not corrected wrt the real robot (ie: rotated over 180
                 degrees)
      -->
    <origin rpy="0 0 -3.14159265359" xyz="0 0 0"/>
    <parent link="a_bot_base_link"/>
    <child link="a_bot_base"/>
  </joint>
  <!-- Frame coincident with all-zeros TCP on UR controller -->
  <link name="a_bot_tool0"/>
  <joint name="a_bot_wrist_3_link-tool0_fixed_joint" type="fixed">
    <origin rpy="0 0 0" xyz="0 0 0"/>
    <parent link="a_bot_wrist_3_link"/>
    <child link="a_bot_tool0"/>
  </joint>
  <!-- measured from model -->
  <!-- link lengths used in model -->
  <!-- manually measured -->
  <link name="b_bot_base_link">
    <visual>
      <origin rpy="0 0 3.14159265359" xyz="0 0 0"/>
      <geometry>
        <mesh filename="package://ur_e_description/meshes/ur5e/visual/base.dae"/>
      </geometry>
      <material name="LightGrey">
        <color rgba="0.7 0.7 0.7 1.0"/>
      </material>
    </visual>
    <collision>
      <origin rpy="0 0 3.14159265359" xyz="0 0 0"/>
      <geometry>
        <mesh filename="package://ur_e_description/meshes/ur5e/collision/base.stl"/>
      </geometry>
    </collision>
    <inertial>
      <mass value="4.0"/>
      <origin rpy="0 0 0" xyz="0.0 0.0 0.0"/>
      <inertia ixx="0.00443333156" ixy="0.0" ixz="0.0" iyy="0.00443333156" iyz="0.0" izz="0.0072"/>
    </inertial>
  </link>
  <joint name="b_bot_shoulder_pan_joint" type="revolute">
    <parent link="b_bot_base_link"/>
    <child link="b_bot_shoulder_link"/>
    <origin rpy="0 0 3.14159267617" xyz="0 0 0.162724395221"/>
    <axis xyz="0 0 1"/>
    <limit effort="150.0" lower="-3.14159265359" upper="3.14159265359" velocity="3.14"/>
    <dynamics damping="0.0" friction="0.0"/>
  </joint>
  <link name="b_bot_shoulder_link">
    <visual>
      <origin rpy="0 0 3.14159265359" xyz="0 0 0"/>
      <geometry>
        <mesh filename="package://ur_e_description/meshes/ur5e/visual/shoulder.dae"/>
      </geometry>
      <material name="LightGrey">
        <color rgba="0.7 0.7 0.7 1.0"/>
      </material>
    </visual>
    <collision>
      <origin rpy="0 0 3.14159265359" xyz="0 0 0"/>
      <geometry>
        <mesh filename="package://ur_e_description/meshes/ur5e/collision/shoulder.stl"/>
      </geometry>
    </collision>
    <inertial>
      <mass value="3.7"/>
      <origin rpy="0 0 0" xyz="0.0 0.0 0.0"/>
      <inertia ixx="0.010267495893" ixy="0.0" ixz="0.0" iyy="0.010267495893" iyz="0.0" izz="0.00666"/>
    </inertial>
  </link>
  <joint name="b_bot_shoulder_lift_joint" type="revolute">
    <parent link="b_bot_shoulder_link"/>
    <child link="b_bot_upper_arm_link"/>
    <origin rpy="1.56924920236 0 -4.14261094479e-06" xyz="9.64953533374e-05 0 0"/>
    <axis xyz="0 0 1"/>
    <limit effort="150.0" lower="-3.14159265359" upper="3.14159265359" velocity="3.14"/>
    <dynamics damping="0.0" friction="0.0"/>
  </joint>
  <link name="b_bot_upper_arm_link">
    <visual>
      <origin rpy="1.57079632679 0 -1.57079632679" xyz="0 0 0.138"/>
      <geometry>
        <mesh filename="package://ur_e_description/meshes/ur5e/visual/upperarm.dae"/>
      </geometry>
      <material name="LightGrey">
        <color rgba="0.7 0.7 0.7 1.0"/>
      </material>
    </visual>
    <collision>
      <origin rpy="1.57079632679 0 -1.57079632679" xyz="0 0 0.138"/>
      <geometry>
        <mesh filename="package://ur_e_description/meshes/ur5e/collision/upperarm.stl"/>
      </geometry>
    </collision>
    <inertial>
      <mass value="8.393"/>
      <origin rpy="0 1.57079632679 0" xyz="-0.212740278723 0.0 0.138"/>
      <inertia ixx="0.138420591223" ixy="0.0" ixz="0.0" iyy="0.138420591223" iyz="0.0" izz="0.0236053125"/>
    </inertial>
  </link>
  <joint name="b_bot_elbow_joint" type="revolute">
    <parent link="b_bot_upper_arm_link"/>
    <child link="b_bot_forearm_link"/>
    <origin rpy="0.00259171651927 0.00199753913186 -3.75661172549e-06" xyz="-0.425480557447 0 0"/>
    <axis xyz="0 0 1"/>
    <limit effort="150.0" lower="0.0" upper="3.14159265359" velocity="3.14"/>
    <dynamics damping="0.0" friction="0.0"/>
  </joint>
  <link name="b_bot_forearm_link">
    <visual>
      <origin rpy="1.57079632679 0 -1.57079632679" xyz="0 0 0.007"/>
      <geometry>
        <mesh filename="package://ur_e_description/meshes/ur5e/visual/forearm.dae"/>
      </geometry>
      <material name="LightGrey">
        <color rgba="0.7 0.7 0.7 1.0"/>
      </material>
    </visual>
    <collision>
      <origin rpy="1.57079632679 0 -1.57079632679" xyz="0 0 0.007"/>
      <geometry>
        <mesh filename="package://ur_e_description/meshes/ur5e/collision/forearm.stl"/>
      </geometry>
    </collision>
    <inertial>
      <mass value="2.275"/>
      <origin rpy="0 1.57079632679 0" xyz="-0.212740278723 0.0 0.007"/>
      <inertia ixx="0.0324257328349" ixy="0.0" ixz="0.0" iyy="0.0324257328349" iyz="0.0" izz="0.0063984375"/>
    </inertial>
  </link>
  <joint name="b_bot_wrist_1_joint" type="revolute">
    <parent link="b_bot_forearm_link"/>
    <child link="b_bot_wrist_1_link"/>
    <origin rpy="0.00508052111367 -0.00111435703832 9.34596214069e-06" xyz="-0.392634564131 -0.000678760909611 0.133599497852"/>
    <axis xyz="0 0 1"/>
    <limit effort="28.0" lower="-4.71238898038" upper="3.14159265359" velocity="6.28"/>
    <dynamics damping="0.0" friction="0.0"/>
  </joint>
  <link name="b_bot_wrist_1_link">
    <visual>
      <origin rpy="1.57079632679 0 0" xyz="0 0 -0.127"/>
      <geometry>
        <mesh filename="package://ur_e_description/meshes/ur5e/visual/wrist1.dae"/>
      </geometry>
      <material name="LightGrey">
        <color rgba="0.7 0.7 0.7 1.0"/>
      </material>
    </visual>
    <collision>
      <origin rpy="1.57079632679 0 0" xyz="0 0 -0.127"/>
      <geometry>
        <mesh filename="package://ur_e_description/meshes/ur5e/collision/wrist1.stl"/>
      </geometry>
    </collision>
    <inertial>
      <mass value="1.219"/>
      <origin rpy="0 0 0" xyz="0.0 0.0 0.0"/>
      <inertia ixx="0.00272373426647" ixy="0.0" ixz="0.0" iyy="0.00272373426647" iyz="0.0" izz="0.0034284375"/>
    </inertial>
  </link>
  <joint name="b_bot_wrist_2_joint" type="revolute">
    <parent link="b_bot_wrist_1_link"/>
    <child link="b_bot_wrist_2_link"/>
    <origin rpy="1.57004089757 0 -5.34635573056e-07" xyz="0.000117873220402 -0.0996886015847 7.53076970315e-05"/>
    <axis xyz="0 0 1"/>
    <limit effort="28.0" lower="-4.71238898038" upper="4.71238898038" velocity="6.28"/>
    <dynamics damping="0.0" friction="0.0"/>
  </joint>
  <link name="b_bot_wrist_2_link">
    <visual>
      <origin rpy="0 0 0" xyz="0 0 -0.0997"/>
      <geometry>
        <mesh filename="package://ur_e_description/meshes/ur5e/visual/wrist2.dae"/>
      </geometry>
      <material name="LightGrey">
        <color rgba="0.7 0.7 0.7 1.0"/>
      </material>
    </visual>
    <collision>
      <origin rpy="0 0 0" xyz="0 0 -0.0997"/>
      <geometry>
        <mesh filename="package://ur_e_description/meshes/ur5e/collision/wrist2.stl"/>
      </geometry>
    </collision>
    <inertial>
      <mass value="1.219"/>
      <origin rpy="0 0 0" xyz="0.0 0.0 0.0"/>
      <inertia ixx="0.00271989988732" ixy="0.0" ixz="0.0" iyy="0.00271989988732" iyz="0.0" izz="0.0034284375"/>
    </inertial>
  </link>
  <joint name="b_bot_wrist_3_joint" type="revolute">
    <parent link="b_bot_wrist_2_link"/>
    <child link="b_bot_wrist_3_link"/>
    <origin rpy="1.57137404126 3.14159265359 -3.14159262873" xyz="1.49712550875e-05 0.0994991011347 5.748207633e-05"/>
    <axis xyz="0 0 1"/>
    <limit effort="28.0" lower="-6.28318530718" upper="6.28318530718" velocity="6.28"/>
    <dynamics damping="0.0" friction="0.0"/>
  </joint>
  <link name="b_bot_wrist_3_link">
    <visual>
      <origin rpy="1.57079632679 0 0" xyz="0 0 -0.0989"/>
      <geometry>
        <mesh filename="package://ur_e_description/meshes/ur5e/visual/wrist3.dae"/>
      </geometry>
      <material name="LightGrey">
        <color rgba="0.7 0.7 0.7 1.0"/>
      </material>
    </visual>
    <collision>
      <origin rpy="1.57079632679 0 0" xyz="0 0 -0.0989"/>
      <geometry>
        <mesh filename="package://ur_e_description/meshes/ur5e/collision/wrist3.stl"/>
      </geometry>
    </collision>
    <inertial>
      <mass value="0.1879"/>
      <origin rpy="0 0 0" xyz="0.0 0.0 -0.025"/>
      <inertia ixx="0.000134270154625" ixy="0.0" ixz="0.0" iyy="0.000134270154625" iyz="0.0" izz="0.00019024875"/>
    </inertial>
  </link>
  <joint name="b_bot_ee_fixed_joint" type="fixed">
    <parent link="b_bot_wrist_3_link"/>
    <child link="b_bot_ee_link"/>
    <origin rpy="0.0 -1.57079632679 1.57079632679" xyz="0.0 0.0 0.0"/>
  </joint>
  <link name="b_bot_ee_link">
    <collision>
      <geometry>
        <box size="0.01 0.01 0.01"/>
      </geometry>
      <origin rpy="0 0 0" xyz="-0.01 0 0"/>
    </collision>
  </link>
  <transmission name="b_bot_shoulder_pan_trans">
    <type>transmission_interface/SimpleTransmission</type>
    <joint name="b_bot_shoulder_pan_joint">
      <hardwareInterface>hardware_interface/PositionJointInterface</hardwareInterface>
    </joint>
    <actuator name="b_bot_shoulder_pan_motor">
      <mechanicalReduction>1</mechanicalReduction>
    </actuator>
  </transmission>
  <transmission name="b_bot_shoulder_lift_trans">
    <type>transmission_interface/SimpleTransmission</type>
    <joint name="b_bot_shoulder_lift_joint">
      <hardwareInterface>hardware_interface/PositionJointInterface</hardwareInterface>
    </joint>
    <actuator name="b_bot_shoulder_lift_motor">
      <mechanicalReduction>1</mechanicalReduction>
    </actuator>
  </transmission>
  <transmission name="b_bot_elbow_trans">
    <type>transmission_interface/SimpleTransmission</type>
    <joint name="b_bot_elbow_joint">
      <hardwareInterface>hardware_interface/PositionJointInterface</hardwareInterface>
    </joint>
    <actuator name="b_bot_elbow_motor">
      <mechanicalReduction>1</mechanicalReduction>
    </actuator>
  </transmission>
  <transmission name="b_bot_wrist_1_trans">
    <type>transmission_interface/SimpleTransmission</type>
    <joint name="b_bot_wrist_1_joint">
      <hardwareInterface>hardware_interface/PositionJointInterface</hardwareInterface>
    </joint>
    <actuator name="b_bot_wrist_1_motor">
      <mechanicalReduction>1</mechanicalReduction>
    </actuator>
  </transmission>
  <transmission name="b_bot_wrist_2_trans">
    <type>transmission_interface/SimpleTransmission</type>
    <joint name="b_bot_wrist_2_joint">
      <hardwareInterface>hardware_interface/PositionJointInterface</hardwareInterface>
    </joint>
    <actuator name="b_bot_wrist_2_motor">
      <mechanicalReduction>1</mechanicalReduction>
    </actuator>
  </transmission>
  <transmission name="b_bot_wrist_3_trans">
    <type>transmission_interface/SimpleTransmission</type>
    <joint name="b_bot_wrist_3_joint">
      <hardwareInterface>hardware_interface/PositionJointInterface</hardwareInterface>
    </joint>
    <actuator name="b_bot_wrist_3_motor">
      <mechanicalReduction>1</mechanicalReduction>
    </actuator>
  </transmission>
  <gazebo reference="b_bot_shoulder_link">
    <selfCollide>true</selfCollide>
  </gazebo>
  <gazebo reference="b_bot_upper_arm_link">
    <selfCollide>true</selfCollide>
  </gazebo>
  <gazebo reference="b_bot_forearm_link">
    <selfCollide>true</selfCollide>
  </gazebo>
  <gazebo reference="b_bot_wrist_1_link">
    <selfCollide>true</selfCollide>
  </gazebo>
  <gazebo reference="b_bot_wrist_3_link">
    <selfCollide>true</selfCollide>
  </gazebo>
  <gazebo reference="b_bot_wrist_2_link">
    <selfCollide>true</selfCollide>
  </gazebo>
  <gazebo reference="b_bot_ee_link">
    <selfCollide>true</selfCollide>
  </gazebo>
  <!-- ROS base_link to UR 'Base' Coordinates transform -->
  <link name="b_bot_base"/>
  <joint name="b_bot_base_link-base_fixed_joint" type="fixed">
    <!-- NOTE: this rotation is only needed as long as base_link itself is
                 not corrected wrt the real robot (ie: rotated over 180
                 degrees)
      -->
    <origin rpy="0 0 -3.14159265359" xyz="0 0 0"/>
    <parent link="b_bot_base_link"/>
    <child link="b_bot_base"/>
  </joint>
  <!-- Frame coincident with all-zeros TCP on UR controller -->
  <link name="b_bot_tool0"/>
  <joint name="b_bot_wrist_3_link-tool0_fixed_joint" type="fixed">
    <origin rpy="0 0 0" xyz="0 0 0"/>
    <parent link="b_bot_wrist_3_link"/>
    <child link="b_bot_tool0"/>
  </joint>
  <link name="my_ground"/>
  <joint name="world_a_bot_joint" type="fixed">
    <parent link="my_ground"/>
    <child link="a_bot_base_link"/>
    <origin rpy="0.0 0.0 0.0" xyz="-0.004 -0.525 0.75"/>
  </joint>
  <joint name="world_b_bot_joint" type="fixed">
    <parent link="my_ground"/>
    <child link="b_bot_base_link"/>
    <origin rpy="0.0 0.0 -3.141" xyz="-0.0 0.525 0.75"/>
  </joint>
  <link name="world"/>
  <joint name="world_my_joint" type="fixed">
    <parent link="world"/>
    <child link="my_ground"/>
    <origin rpy="0.0 0.0 0.0" xyz="0.0 0.0 0.0"/>
  </joint>
</robot>

